Workbook

Sheet Dashboard
A1: Microsoft Autopilot Project Dashboard - Updated
A3: Project Overview | D3: Critical Applications
A4: Total Tasks: | B4: =COUNTA('Task Tracking'!A2:A1000)-COUNTBLANK('Task Tracking'!A2:A1000) | D4: Security Apps (CrowdStrike, Absolute): | E4: =COUNTIFS('Task Tracking'!B:B,"Phase 2",'Task Tracking'!C:C,"*CrowdStrike*",'Task Tracking'!F:F,"Completed")+COUNTIFS('Task Tracking'!B:B,"Phase 2",'Task Tracking'!C:C,"*Absolute*",'Task Tracking'!F:F,"Completed")
A5: Completed Tasks: | B5: =COUNTIF('Task Tracking'!F:F,"Completed") | D5: VPN & Authentication Apps: | E5: =COUNTIFS('Task Tracking'!B:B,"Phase 2",'Task Tracking'!C:C,"*VPN*",'Task Tracking'!F:F,"Completed")+COUNTIFS('Task Tracking'!B:B,"Phase 2",'Task Tracking'!C:C,"*Duo*",'Task Tracking'!F:F,"Completed")
A6: In Progress Tasks: | B6: =COUNTIF('Task Tracking'!F:F,"In Progress") | D6: Security Policies Applied: | E6: =COUNTIFS('Task Tracking'!B:B,"Phase 2",'Task Tracking'!C:C,"*CIS*",'Task Tracking'!F:F,"Completed")+COUNTIFS('Task Tracking'!B:B,"Phase 2",'Task Tracking'!C:C,"*Defender*",'Task Tracking'!F:F,"Completed")
A7: Not Started Tasks: | B7: =COUNTIF('Task Tracking'!F:F,"Not Started")
A8: Project Progress: | B8: =IF((B5+B6+B7)>0,B5/(B5+B6+B7),0) | D8: Phase Progress
D9: Phase 1 (Infrastructure): | E9: =IF(COUNTIF('Task Tracking'!B:B,"Phase 1")>0,COUNTIFS('Task Tracking'!B:B,"Phase 1",'Task Tracking'!F:F,"Completed")/COUNTIF('Task Tracking'!B:B,"Phase 1"),0)
A10: Issue Summary | D10: Phase 2 (Apps & Policies): | E10: =IF(COUNTIF('Task Tracking'!B:B,"Phase 2")>0,COUNTIFS('Task Tracking'!B:B,"Phase 2",'Task Tracking'!F:F,"Completed")/COUNTIF('Task Tracking'!B:B,"Phase 2"),0)
A11: Open Issues: | B11: =COUNTIF('Issue Tracking'!I:I,"Open") | D11: Phase 3 (Device Naming): | E11: =IF(COUNTIF('Task Tracking'!B:B,"Phase 3")>0,COUNTIFS('Task Tracking'!B:B,"Phase 3",'Task Tracking'!F:F,"Completed")/COUNTIF('Task Tracking'!B:B,"Phase 3"),0)
A12: In Progress Issues: | B12: =COUNTIF('Issue Tracking'!I:I,"In Progress") | D12: Phase 4 (Co-management): | E12: =IF(COUNTIF('Task Tracking'!B:B,"Phase 4")>0,COUNTIFS('Task Tracking'!B:B,"Phase 4",'Task Tracking'!F:F,"Completed")/COUNTIF('Task Tracking'!B:B,"Phase 4"),0)
A13: Critical Issues: | B13: =COUNTIFS('Issue Tracking'!G:G,"Critical",'Issue Tracking'!I:I,"<>Resolved")
A14: High Priority Issues: | B14: =COUNTIFS('Issue Tracking'!G:G,"High",'Issue Tracking'!I:I,"<>Resolved") | D14: Feasibility Testing & Deployment Modes
D15: User-Driven Feasibility: | E15: =COUNTIFS('Task Tracking'!C:C,"*Feasibility*",'Task Tracking'!F:F,"Completed")
A16: Resource Utilization | D16: Deployment Mode Framework: | E16: =COUNTIFS('Task Tracking'!C:C,"*Decision Matrix*",'Task Tracking'!F:F,"Completed")
A17: Total Estimated Hours: | B17: =SUM('Task Tracking'!L:L) | D17: Pre-Provisioning Testing: | E17: =COUNTIFS('Task Tracking'!C:C,"*Pre-Provisioning*",'Task Tracking'!F:F,"Completed")
A18: Total Actual Hours: | B18: =SUM('Task Tracking'!M:M)
A19: Hours Variance: | B19: =B18-B17 | D19: Critical Success Metrics
D20: Critical Tasks Completed: | E20: =COUNTIFS('Task Tracking'!G:G,"Critical",'Task Tracking'!F:F,"Completed")
D21: Security Issues Open: | E21: =COUNTIFS('Issue Tracking'!F:F,"Security*",'Issue Tracking'!I:I,"Open")
D22: Feasibility Issues Open: | E22: =COUNTIFS('Issue Tracking'!F:F,"*Feasibility*",'Issue Tracking'!I:I,"Open")

Sheet Task Tracking
A1: Task ID | B1: Phase | C1: Task Name | D1: Description | E1: Owner | F1: Status | G1: Priority | H1: Start Date | I1: Due Date | J1: Completion Date | K1: % Complete | L1: Estimated Hours | M1: Actual Hours | N1: Dependencies | O1: Notes
A2: T001 | B2: Phase 1 | C2: Verify Azure AD Premium Licensing | D2: Confirm sufficient P1/P2 licenses for Autopilot | E2: Infrastructure Team | F2: Not Started | G2: High | H2: 2024-02-07 | I2: 2024-02-09 | K2: 0 | L2: 4 | M2: 0 | O2: Check current license count
A3: T002 | B3: Phase 1 | C3: Validate Intune Licensing | D3: Ensure device licenses available | E3: Infrastructure Team | F3: Not Started | G3: High | H3: 2024-02-07 | I3: 2024-02-09 | K3: 0 | L3: 2 | M3: 0 | N3: T001
A4: T003 | B4: Phase 1 | C4: Install Intune Connector | D4: Install connector on pre-prod server | E4: Infrastructure Team | F4: Not Started | G4: Critical | H4: 2024-02-10 | I4: 2024-02-14 | K4: 0 | L4: 8 | M4: 0 | N4: T001,T002 | O4: Requires domain admin access
A5: T004 | B5: Phase 1 | C5: Configure Service Account | D5: Create dedicated service account with domain join permissions | E5: Security Team | F5: Not Started | G5: Critical | H5: 2024-02-10 | I5: 2024-02-12 | K5: 0 | L5: 4 | M5: 0
A6: T005 | B6: Phase 1 | C6: Test Connector Communication | D6: Verify connector can communicate with Intune | E6: Infrastructure Team | F6: Not Started | G6: High | H6: 2024-02-13 | I6: 2024-02-14 | K6: 0 | L6: 3 | M6: 0 | N6: T003,T004
A7: T006 | B7: Phase 1 | C7: Autopilot Mode Feasibility Assessment | D7: Test User-Driven vs Pre-Provisioning deployment modes | E7: QA Team | F7: Not Started | G7: Critical | H7: 2024-02-12 | I7: 2024-02-18 | K7: 0 | L7: 20 | M7: 0 | N7: T005 | O7: Test 15-20 devices each mode
A8: T007 | B8: Phase 1 | C8: Network Connectivity Testing | D8: Test VPN and hybrid join across user locations | E8: Network Team | F8: Not Started | G8: High | H8: 2024-02-15 | I8: 2024-02-19 | K8: 0 | L8: 12 | M8: 0 | N8: T006 | O8: Test multiple scenarios
A9: T008 | B9: Phase 1 | C9: User Experience Validation | D9: Conduct UAT with representative user groups | E9: QA Team | F9: Not Started | G9: High | H9: 2024-02-16 | I9: 2024-02-20 | K9: 0 | L9: 16 | M9: 0 | N9: T006 | O9: Different skill levels
A10: T009 | B10: Phase 1 | C10: Deployment Mode Decision Matrix | D10: Create framework for mode selection | E10: Project Manager | F10: Not Started | G10: Critical | H10: 2024-02-19 | I10: 2024-02-21 | K10: 0 | L10: 8 | M10: 0 | N10: T006,T007,T008 | O10: Document decision criteria
A11: T010 | B11: Phase 2 | C11: Package CrowdStrike Windows Sensor | D11: Create Win32 app with organization CID | E11: Security Team | F11: Not Started | G11: Critical | H11: 2024-02-22 | I11: 2024-02-26 | K11: 0 | L11: 12 | M11: 0 | N11: T009 | O11: Must install before domain join
A12: T011 | B12: Phase 2 | C12: Package Cisco Secure VPN Client | D12: Create Win32 app for VPN deployment | E12: Network Team | F12: Not Started | G12: Critical | H12: 2024-02-22 | I12: 2024-02-26 | K12: 0 | L12: 10 | M12: 0 | N12: T009 | O12: Pre-logon capability required
A13: T012 | B13: Phase 2 | C13: Configure VPN Certificates | D13: Deploy machine certificates for VPN auth | E13: Security Team | F13: Not Started | G13: Critical | H13: 2024-02-24 | I13: 2024-02-28 | K13: 0 | L13: 8 | M13: 0 | N13: T011
A14: T013 | B14: Phase 2 | C14: Package Absolute Agent | D14: Create Win32 app with server settings | E14: Security Team | F14: Not Started | G14: High | H14: 2024-02-26 | I14: 2024-03-02 | K14: 0 | L14: 6 | M14: 0 | N14: T010
A15: T014 | B15: Phase 2 | C15: Package Duo for Windows Logon | D15: Configure with integration keys | E15: Security Team | F15: Not Started | G15: High | H15: 2024-02-27 | I15: 2024-03-05 | K15: 0 | L15: 8 | M15: 0
A16: T015 | B16: Phase 2 | C16: Package EPASS | D16: Password management app with domain dependency | E16: Application Team | F16: Not Started | G16: Medium | H16: 2024-03-01 | I16: 2024-03-07 | K16: 0 | L16: 6 | M16: 0 | O16: Domain join required
A17: T016 | B17: Phase 2 | C17: Configure Company Portal | D17: Setup with corporate branding | E17: Application Team | F17: Not Started | G17: High | H17: 2024-02-26 | I17: 2024-03-02 | K17: 0 | L17: 4 | M17: 0
A18: T017 | B18: Phase 2 | C18: Package Chrome Browser | D18: Enterprise policies and configuration | E18: Application Team | F18: Not Started | G18: Medium | H18: 2024-03-03 | I18: 2024-03-07 | K18: 0 | L18: 4 | M18: 0
A19: T018 | B19: Phase 2 | C19: Windows Enterprise Edition Policy | D19: Create upgrade policy from Pro to Enterprise | E19: Infrastructure Team | F19: Not Started | G19: Critical | H19: 2024-02-24 | I19: 2024-02-28 | K19: 0 | L19: 6 | M19: 0 | N19: T009 | O19: Must run early in Autopilot
A20: T019 | B20: Phase 2 | C20: CIS Baseline Policies | D20: Import and configure Level 1 baseline | E20: Security Team | F20: Not Started | G20: High | H20: 2024-02-26 | I20: 2024-03-04 | K20: 0 | L20: 12 | M20: 0
A21: T020 | B21: Phase 2 | C21: Defender Onboarding Package | D21: Deploy organization-specific package | E21: Security Team | F21: Not Started | G21: Critical | H21: 2024-02-27 | I21: 2024-03-05 | K21: 0 | L21: 8 | M21: 0
A22: T021 | B22: Phase 2 | C22: Defender AV and Firewall Config | D22: Configure real-time protection and firewall | E22: Security Team | F22: Not Started | G22: High | H22: 2024-03-01 | I22: 2024-03-07 | K22: 0 | L22: 6 | M22: 0 | N22: T020
A23: T022 | B23: Phase 2 | C23: USB Storage Restrictions | D23: Evaluate and configure access controls | E23: Security Team | F23: Not Started | G23: Medium | H23: 2024-03-03 | I23: 2024-03-09 | K23: 0 | L23: 4 | M23: 0 | O23: Business approval needed
A24: T023 | B24: Phase 3 | C24: Design Device Naming Convention | D24: Establish naming standards and templates | E24: Infrastructure Team | F24: Not Started | G24: High | H24: 2024-03-08 | I24: 2024-03-12 | K24: 0 | L24: 8 | M24: 0 | N24: T022
A25: T024 | B25: Phase 3 | C25: Create Autopilot Profiles by Department | D25: IT, HR, Finance, Executive profiles | E25: Infrastructure Team | F25: Not Started | G25: High | H25: 2024-03-10 | I25: 2024-03-14 | K25: 0 | L25: 12 | M25: 0 | N25: T023
A26: T025 | B26: Phase 3 | C26: Develop PowerShell Naming Script | D26: Fallback script for custom naming | E26: Infrastructure Team | F26: Not Started | G26: Medium | H26: 2024-03-12 | I26: 2024-03-16 | K26: 0 | L26: 8 | M26: 0 | N26: T023
A27: T026 | B27: Phase 3 | C27: Create IT Depot Manual Procedure | D27: Backup manual naming process | E27: Process Team | F27: Not Started | G27: Low | H27: 2024-03-13 | I27: 2024-03-17 | K27: 0 | L27: 4 | M27: 0 | N27: T023
A28: T027 | B28: Phase 3 | C28: Test Device Naming Scenarios | D28: Test all naming approaches | E28: QA Team | F28: Not Started | G28: High | H28: 2024-03-15 | I28: 2024-03-19 | K28: 0 | L28: 8 | M28: 0 | N28: T024,T025
A29: T028 | B29: Phase 3 | C29: Validate Deployment Mode Assignments | D29: Apply decision matrix to test scenarios | E29: Project Manager | F29: Not Started | G29: High | H29: 2024-03-17 | I29: 2024-03-21 | K29: 0 | L29: 6 | M29: 0 | N29: T027 | O29: Ensure correct mode selection
A30: T029 | B30: Phase 4 | C30: Enable Co-management in SCCM | D30: Configure SCCM for co-management | E30: SCCM Team | F30: Not Started | G30: High | H30: 2024-03-20 | I30: 2024-03-24 | K30: 0 | L30: 6 | M30: 0 | N30: T028
A31: T030 | B31: Phase 4 | C31: Package SCCM Client | D31: Create Intune app for SCCM client | E31: SCCM Team | F31: Not Started | G31: Critical | H31: 2024-03-22 | I31: 2024-03-26 | K31: 0 | L31: 10 | M31: 0 | N31: T029
A32: T031 | B32: Phase 4 | C32: Configure Application Sequencing | D32: Set installation order for all apps | E32: Application Team | F32: Not Started | G32: High | H32: 2024-03-24 | I32: 2024-03-28 | K32: 0 | L32: 8 | M32: 0 | N32: T030
A33: T032 | B33: Phase 4 | C33: Test Pre-Provisioning Workflow | D33: Validate white glove deployment process | E33: QA Team | F33: Not Started | G33: High | H33: 2024-03-26 | I33: 2024-04-01 | K33: 0 | L33: 16 | M33: 0 | N33: T031 | O33: For devices requiring this mode
A34: T033 | B34: Phase 5 | C34: Security Application Testing | D34: Test CrowdStrike, Absolute, Defender deployment | E34: Security Team | F34: Not Started | G34: Critical | H34: 2024-03-29 | I34: 2024-04-05 | K34: 0 | L34: 24 | M34: 0 | N34: T032 | O34: Test 10 devices each mode
A35: T034 | B35: Phase 5 | C35: VPN and Authentication Testing | D35: Test VPN, Duo, domain join process | E35: Network Team | F35: Not Started | G35: Critical | H35: 2024-04-01 | I35: 2024-04-08 | K35: 0 | L35: 20 | M35: 0 | N35: T032
A36: T035 | B36: Phase 5 | C36: Device Naming Validation | D36: Verify all naming conventions work | E36: Infrastructure Team | F36: Not Started | G36: High | H36: 2024-04-03 | I36: 2024-04-09 | K36: 0 | L36: 12 | M36: 0 | N36: T033,T034
A37: T036 | B37: Phase 5 | C37: Deployment Mode Performance Testing | D37: Compare User-Driven vs Pre-Provisioning metrics | E37: QA Team | F37: Not Started | G37: High | H37: 2024-04-05 | I37: 2024-04-11 | K37: 0 | L37: 16 | M37: 0 | N37: T035 | O37: Timing and success rates
A38: T037 | B38: Phase 5 | C38: End-to-End Pilot Testing | D38: Complete deployment testing | E38: QA Team | F38: Not Started | G38: Critical | H38: 2024-04-08 | I38: 2024-04-15 | K38: 0 | L38: 40 | M38: 0 | N38: T036 | O38: 20 pilot devices - mixed modes
A39: T038 | B39: Phase 5 | C39: Performance Optimization | D39: Optimize deployment speed and reliability | E39: Infrastructure Team | F39: Not Started | G39: Medium | H39: 2024-04-10 | I39: 2024-04-16 | K39: 0 | L39: 16 | M39: 0 | N39: T037
A40: T039 | B40: Phase 6 | C40: Security Team Training | D40: Train on new security applications | E40: Security Team | F40: Not Started | G40: High | H40: 2024-04-15 | I40: 2024-04-19 | K40: 0 | L40: 8 | M40: 0 | N40: T038
...

Sheet Issue Tracking
A1: Issue ID | B1: Date Reported | C1: Reported By | D1: Issue Title | E1: Description | F1: Category | G1: Severity | H1: Priority | I1: Status | J1: Assigned To | K1: Related Task ID | L1: Root Cause | M1: Resolution | N1: Date Resolved | O1: Resolution Time (Hours) | P1: Follow-up Required | Q1: Notes
A2: I001 | B2: 2024-02-08 | C2: John Smith | D2: CrowdStrike Package Installation Failed | E2: CrowdStrike sensor fails to install during Autopilot | F2: Security Applications | G2: Critical | H2: Critical | I2: Open | J2: Security Team | K2: T010 | P2: Yes | Q2: May need manual CID configuration
A3: I002 | B3: 2024-02-12 | C3: Jane Doe | D3: VPN Certificate Deployment Issue | E3: Machine certificates not deploying to test devices | F3: Security | G3: High | H3: High | I3: In Progress | J3: Security Team | K3: T012 | L3: Certificate template permissions | P3: No | Q3: Working with CA team
A4: I003 | B4: 2024-02-15 | C4: Mike Johnson | D4: Windows Enterprise Upgrade Failure | E4: Devices not upgrading from Pro to Enterprise | F4: System Configuration | G4: Critical | H4: Critical | I4: Open | J4: Infrastructure Team | K4: T018 | P4: Yes | Q4: License key may be invalid
A5: I004 | B5: 2024-02-18 | C5: Sarah Wilson | D5: Autopilot Profile Assignment | E5: Devices getting assigned to wrong department profile | F5: Device Management | G5: Medium | H5: High | I5: Open | J5: Infrastructure Team | K5: T024 | P5: No | Q5: Review group targeting rules
A6: I005 | B6: 2024-02-20 | C6: David Brown | D6: Duo Installation Timing | E6: Duo installing before domain join causing issues | F6: Authentication | G6: Medium | H6: Medium | I6: Open | J6: Security Team | K6: T014 | P6: No | Q6: Need to adjust installation sequence
A7: I006 | B7: 2024-02-22 | C7: Lisa Garcia | D7: CIS Baseline Policy Conflicts | E7: Some CIS policies conflicting with app installations | F7: Security Policies | G7: High | H7: High | I7: Open | J7: Security Team | K7: T019 | P7: Yes | Q7: May need policy exceptions
A8: I007 | B8: 2024-02-24 | C8: Tom Anderson | D8: Device Naming Character Limit | E8: Some department codes exceed 15-character limit | F8: Device Naming | G8: Medium | H8: Medium | I8: Open | J8: Infrastructure Team | K8: T023 | P8: No | Q8: Need shorter department codes
A9: I008 | B9: 2024-02-25 | C9: Amy Chen | D9: Absolute Agent Silent Install | E9: Absolute Agent not installing silently | F9: Security Applications | G9: Medium | H9: Low | I9: Open | J9: Security Team | K9: T013 | P9: No | Q9: Check installation parameters
A10: I009 | B10: 2024-02-14 | C10: Mark Rodriguez | D10: User-Driven Deployment Timing | E10: User-driven deployment exceeding 90 minutes | F10: Feasibility Testing | G10: High | H10: High | I10: Open | J10: QA Team | K10: T006 | P10: Yes | Q10: May need Pre-Provisioning for some users
A11: I010 | B11: 2024-02-16 | C11: Jennifer Kim | D11: Network Bandwidth Limitations | E11: Slow application downloads affecting deployment time | F11: Network Performance | G11: Medium | H11: Medium | I11: Open | J11: Network Team | K11: T007 | P11: No | Q11: Consider app size optimization
A12: I011 | B12: 2024-02-17 | C12: Robert Chen | D12: User Experience Complexity | E12: Non-technical users struggling with setup process | F12: User Experience | G12: Medium | H12: High | I12: Open | J12: QA Team | K12: T008 | P12: Yes | Q12: May require Pre-Provisioning or training
A13: I012 | B13: 2024-02-19 | C13: Michelle Davis | D13: Deployment Mode Decision Criteria | E13: Unclear criteria for selecting deployment mode | F13: Process | G13: High | H13: High | I13: Open | J13: Project Manager | K13: T009 | P13: Yes | Q13: Need clear decision matrix documentation
